Workbook

Sheet 0. Mã Supplier
A1: SUPPLIER MANAGEMENT 2025
A3: Date: | B3: 45857
K4: NHÓM SẢN PHẨM
A5: Stt | B5: Supplier Name (Tên nhà cung cấp) | C5: Supplier Code (Mã nhà cung cấp) | D5: Lead time (days) (Thời gian giao hàng) | E5: MOQ | F5: Payment Terms (Phương thức thanh toán) | G5: Delivery Terms (Giao hàng) | H5: Location (Địa điểm) | I5: Key Strengths (Ưu điểm) | J5: Supply Score | K5: Mattress | L5: Gối | M5: Bộ chăn ga | N5: Chăn
A6: 1 | B6: HUY HOÀNG NAM | C6: SUVN0001 | G6: Nội địa | M6: x | N6: x
A7: 2 | B7: HAPPYTOWN SLEEPTECH | C7: SUVN0002 | D7: 15-20 | F7: 30 | G7: Nội địa | K7: x | L7: x
A8: 3 | B8: EVERHOME | C8: SUVN0003 | F8: 60 | G8: Nội địa
A9: 4 | B9: TEXNAM | C9: SUVN0004 | F9: 60 | G9: Nội địa | M9: x
A10: 5 | B10: AP WOOD | C10: SUVN0005 | F10: 60 | G10: Nội địa | N10: x
A11: 6 | B11: POWER X | C11: SUCN0001 | F11: 180 | G11: Quốc tế | K11: x

Sheet 1. Master Data
C1: MASTER LIST PRODUCT CODE
C3: Date update: | D3: 45857 | P3: Tỷ giá usd | R3: 26020 | S3: vnd
C4: Revision: | D4: 1 | E4: Cập nhật lại code của nhóm phụ kiện
B7: Mã sản phẩm | C7: SKU | D7: Category | E7: Ngành hàng | F7: Subcategory code | G7: Subcategory name | H7: ID mã sản phẩm shopee | I7: Variation code | J7: Variation name | K7: Tên Sản Phẩm & kích thước (Cao x Rộng x Dài - cm) | L7: Supplier Code | M7: Brand | N7: Vật liệu chính | O7: Cao | P7: Rộng | Q7: Dài | R7: Net weight | S7: Gross Weight | T7: Đóng gói | U7: Packaget Length (cm) | V7: Packaget Width (cm) | W7: Package height (cm) | X7: Màu | Y7: Min. Order | Z7: Leadtime | AA7: Unit Cost (usd) | AB7: Unit Cost (vnd) | AC7: Giá Vốn (+VAT) | AD7: Sales Price (vnd) | AE7: ABC Class. | AF7: M3
B8: =D8&F8 -> MAT001 | C8: =_xlfn.CONCAT(D8,F8,I8) -> MAT001001 | D8: MAT | E8: Nệm | F8: 001 | G8: T&N Foam | H8: 24893009852 | I8: 001 | J8: =P8&" x "&Q8&" x "&O8&" cm" -> 80 x 200 x 10 cm | K8: =_xlfn.CONCAT(E8," ",G8," ",J8) -> Nệm T&N Foam 80 x 200 x 10 cm | L8: =_xlfn.XLOOKUP(M8,'0. Mã Supplier'!$B:$B,'0. Mã Supplier'!$C:$C,0) -> SUVN0002 | M8: HAPPYTOWN SLEEPTECH | O8: 10 | P8: 80 | Q8: 200 | R8: 0 | S8: 0 | T8: Roll Carton Box | U8: =P8*10+80 -> 880 | V8: 250 | W8: 250 | Y8: 5 | AA8: 0 | AB8: 0 | AC8: =AB8*1.08 -> 0 | AE8: A | AF8: =U8*V8*W8/10^9 -> 0.055
B9: =D9&F9 -> MAT001 | C9: =_xlfn.CONCAT(D9,F9,I9) -> MAT001002 | D9: MAT | E9: Nệm | F9: 001 | G9: T&N Foam | H9: 24893009852 | I9: 002 | J9: =P9&" x "&Q9&" x "&O9&" cm" -> 100 x 200 x 10 cm | K9: =_xlfn.CONCAT(E9," ",G9," ",J9) -> Nệm T&N Foam 100 x 200 x 10 cm | L9: =_xlfn.XLOOKUP(M9,'0. Mã Supplier'!$B:$B,'0. Mã Supplier'!$C:$C,0) -> SUVN0002 | M9: HAPPYTOWN SLEEPTECH | O9: 10 | P9: 100 | Q9: 200 | R9: 0 | S9: 0 | T9: Roll Carton Box | U9: =P9*10+80 -> 1080 | V9: 250 | W9: 250 | Y9: 5 | AA9: 0 | AB9: 0 | AC9: =AB9*1.08 -> 0 | AE9: A | AF9: =U9*V9*W9/10^9 -> 0.0675
B10: =D10&F10 -> MAT001 | C10: =_xlfn.CONCAT(D10,F10,I10) -> MAT001003 | D10: MAT | E10: Nệm | F10: 001 | G10: T&N Foam | H10: 24893009852 | I10: 003 | J10: =P10&" x "&Q10&" x "&O10&" cm" -> 120 x 200 x 10 cm | K10: =_xlfn.CONCAT(E10," ",G10," ",J10) -> Nệm T&N Foam 120 x 200 x 10 cm | L10: =_xlfn.XLOOKUP(M10,'0. Mã Supplier'!$B:$B,'0. Mã Supplier'!$C:$C,0) -> SUVN0002 | M10: HAPPYTOWN SLEEPTECH | O10: 10 | P10: 120 | Q10: 200 | R10: 0 | S10: 0 | T10: Roll Carton Box | U10: =P10*10+80 -> 1280 | V10: 250 | W10: 250 | Y10: 5 | Z10: 15 | AA10: 0 | AB10: 1073100 | AC10: =AB10*1.08 -> 1158948 | AE10: A | AF10: =U10*V10*W10/10^9 -> 0.08
B11: =D11&F11 -> MAT001 | C11: =_xlfn.CONCAT(D11,F11,I11) -> MAT001004 | D11: MAT | E11: Nệm | F11: 001 | G11: T&N Foam | H11: 24893009852 | I11: 004 | J11: =P11&" x "&Q11&" x "&O11&" cm" -> 140 x 200 x 10 cm | K11: =_xlfn.CONCAT(E11," ",G11," ",J11) -> Nệm T&N Foam 140 x 200 x 10 cm | L11: =_xlfn.XLOOKUP(M11,'0. Mã Supplier'!$B:$B,'0. Mã Supplier'!$C:$C,0) -> SUVN0002 | M11: HAPPYTOWN SLEEPTECH | O11: 10 | P11: 140 | Q11: 200 | R11: 0 | S11: 0 | T11: Roll Carton Box | U11: =P11*10+80 -> 1480 | V11: 250 | W11: 250 | Y11: 5 | AA11: 0 | AB11: 0 | AC11: =AB11*1.08 -> 0 | AE11: A | AF11: =U11*V11*W11/10^9 -> 0.0925
B12: =D12&F12 -> MAT001 | C12: =_xlfn.CONCAT(D12,F12,I12) -> MAT001005 | D12: MAT | E12: Nệm | F12: 001 | G12: T&N Foam | H12: 24893009852 | I12: 005 | J12: =P12&" x "&Q12&" x "&O12&" cm" -> 160 x 200 x 10 cm | K12: =_xlfn.CONCAT(E12," ",G12," ",J12) -> Nệm T&N Foam 160 x 200 x 10 cm | L12: =_xlfn.XLOOKUP(M12,'0. Mã Supplier'!$B:$B,'0. Mã Supplier'!$C:$C,0) -> SUVN0002 | M12: HAPPYTOWN SLEEPTECH | O12: 10 | P12: 160 | Q12: 200 | R12: 0 | S12: 0 | T12: Roll Carton Box | U12: =P12*10+80 -> 1680 | V12: 250 | W12: 250 | Y12: 5 | AA12: 0 | AB12: 1421300 | AC12: =AB12*1.08 -> 1535004 | AE12: A | AF12: =U12*V12*W12/10^9 -> 0.105
B13: =D13&F13 -> MAT001 | C13: =_xlfn.CONCAT(D13,F13,I13) -> MAT001006 | D13: MAT | E13: Nệm | F13: 001 | G13: T&N Foam | H13: 24893009852 | I13: 006 | J13: =P13&" x "&Q13&" x "&O13&" cm" -> 180 x 200 x 10 cm | K13: =_xlfn.CONCAT(E13," ",G13," ",J13) -> Nệm T&N Foam 180 x 200 x 10 cm | L13: =_xlfn.XLOOKUP(M13,'0. Mã Supplier'!$B:$B,'0. Mã Supplier'!$C:$C,0) -> SUVN0002 | M13: HAPPYTOWN SLEEPTECH | O13: 10 | P13: 180 | Q13: 200 | R13: 0 | S13: 0 | T13: Roll Carton Box | U13: =P13*10+80 -> 1880 | V13: 250 | W13: 250 | Y13: 5 | AA13: 0 | AB13: 1585400 | AC13: =AB13*1.08 -> 1712232 | AE13: A | AF13: =U13*V13*W13/10^9 -> 0.1175
B14: =D14&F14 -> MAT001 | C14: =_xlfn.CONCAT(D14,F14,I14) -> MAT001007 | D14: MAT | E14: Nệm | F14: 001 | G14: T&N Foam | H14: 24893009852 | I14: 007 | J14: =P14&" x "&Q14&" x "&O14&" cm" -> 200 x 200 x 10 cm | K14: =_xlfn.CONCAT(E14," ",G14," ",J14) -> Nệm T&N Foam 200 x 200 x 10 cm | L14: =_xlfn.XLOOKUP(M14,'0. Mã Supplier'!$B:$B,'0. Mã Supplier'!$C:$C,0) -> SUVN0002 | M14: HAPPYTOWN SLEEPTECH | O14: 10 | P14: 200 | Q14: 200 | R14: 0 | S14: 0 | T14: Roll Carton Box | U14: =P14*10+80 -> 2080 | V14: 250 | W14: 250 | Y14: 5 | AA14: 0 | AB14: 0 | AC14: =AB14*1.08 -> 0 | AE14: A | AF14: =U14*V14*W14/10^9 -> 0.13
B15: =D15&F15 -> MAT001 | C15: =_xlfn.CONCAT(D15,F15,I15) -> MAT001008 | D15: MAT | E15: Nệm | F15: 001 | G15: T&N Foam | H15: 24893009852 | I15: 008 | J15: =P15&" x "&Q15&" x "&O15&" cm" -> 200 x 220 x 10 cm | K15: =_xlfn.CONCAT(E15," ",G15," ",J15) -> Nệm T&N Foam 200 x 220 x 10 cm | L15: =_xlfn.XLOOKUP(M15,'0. Mã Supplier'!$B:$B,'0. Mã Supplier'!$C:$C,0) -> SUVN0002 | M15: HAPPYTOWN SLEEPTECH | O15: 10 | P15: 200 | Q15: 220 | R15: 0 | S15: 0 | T15: Roll Carton Box | U15: =P15*10+80 -> 2080 | V15: 250 | W15: 250 | Y15: 5 | AA15: 0 | AB15: 0 | AC15: =AB15*1.08 -> 0 | AE15: A | AF15: =U15*V15*W15/10^9 -> 0.13
B16: =D16&F16 -> MAT001 | C16: =_xlfn.CONCAT(D16,F16,I16) -> MAT001009 | D16: MAT | E16: Nệm | F16: 001 | G16: T&N Foam | H16: 24893009852 | I16: 009 | J16: =P16&" x "&Q16&" x "&O16&" cm" -> 80 x 200 x 15 cm | K16: =_xlfn.CONCAT(E16," ",G16," ",J16) -> Nệm T&N Foam 80 x 200 x 15 cm | L16: =_xlfn.XLOOKUP(M16,'0. Mã Supplier'!$B:$B,'0. Mã Supplier'!$C:$C,0) -> SUVN0002 | M16: HAPPYTOWN SLEEPTECH | O16: 15 | P16: 80 | Q16: 200 | R16: 0 | S16: 0 | T16: Roll Carton Box | U16: =P16*10+80 -> 880 | V16: 370 | W16: 370 | Y16: 5 | AA16: 0 | AB16: 0 | AC16: =AB16*1.08 -> 0 | AE16: A | AF16: =U16*V16*W16/10^9 -> 0.120472
B17: =D17&F17 -> MAT001 | C17: =_xlfn.CONCAT(D17,F17,I17) -> MAT001010 | D17: MAT | E17: Nệm | F17: 001 | G17: T&N Foam | H17: 24893009852 | I17: 010 | J17: =P17&" x "&Q17&" x "&O17&" cm" -> 100 x 200 x 15 cm | K17: =_xlfn.CONCAT(E17," ",G17," ",J17) -> Nệm T&N Foam 100 x 200 x 15 cm | L17: =_xlfn.XLOOKUP(M17,'0. Mã Supplier'!$B:$B,'0. Mã Supplier'!$C:$C,0) -> SUVN0002 | M17: HAPPYTOWN SLEEPTECH | O17: 15 | P17: 100 | Q17: 200 | R17: 0 | S17: 0 | T17: Roll Carton Box | U17: =P17*10+80 -> 1080 | V17: 370 | W17: 370 | Y17: 5 | AA17: 0 | AB17: 0 | AC17: =AB17*1.08 -> 0 | AE17: A | AF17: =U17*V17*W17/10^9 -> 0.147852
B18: =D18&F18 -> MAT001 | C18: =_xlfn.CONCAT(D18,F18,I18) -> MAT001011 | D18: MAT | E18: Nệm | F18: 001 | G18: T&N Foam | H18: 24893009852 | I18: 011 | J18: =P18&" x "&Q18&" x "&O18&" cm" -> 120 x 200 x 15 cm | K18: =_xlfn.CONCAT(E18," ",G18," ",J18) -> Nệm T&N Foam 120 x 200 x 15 cm | L18: =_xlfn.XLOOKUP(M18,'0. Mã Supplier'!$B:$B,'0. Mã Supplier'!$C:$C,0) -> SUVN0002 | M18: HAPPYTOWN SLEEPTECH | O18: 15 | P18: 120 | Q18: 200 | R18: 0 | S18: 0 | T18: Roll Carton Box | U18: =P18*10+80 -> 1280 | V18: 370 | W18: 370 | Y18: 5 | AA18: 0 | AB18: 0 | AC18: =AB18*1.08 -> 0 | AE18: A | AF18: =U18*V18*W18/10^9 -> 0.175232
B19: =D19&F19 -> MAT001 | C19: =_xlfn.CONCAT(D19,F19,I19) -> MAT001012 | D19: MAT | E19: Nệm | F19: 001 | G19: T&N Foam | H19: 24893009852 | I19: 012 | J19: =P19&" x "&Q19&" x "&O19&" cm" -> 140 x 200 x 15 cm | K19: =_xlfn.CONCAT(E19," ",G19," ",J19) -> Nệm T&N Foam 140 x 200 x 15 cm | L19: =_xlfn.XLOOKUP(M19,'0. Mã Supplier'!$B:$B,'0. Mã Supplier'!$C:$C,0) -> SUVN0002 | M19: HAPPYTOWN SLEEPTECH | O19: 15 | P19: 140 | Q19: 200 | R19: 0 | S19: 0 | T19: Roll Carton Box | U19: =P19*10+80 -> 1480 | V19: 370 | W19: 370 | Y19: 5 | AA19: 0 | AB19: 0 | AC19: =AB19*1.08 -> 0 | AE19: A | AF19: =U19*V19*W19/10^9 -> 0.202612
B20: =D20&F20 -> MAT001 | C20: =_xlfn.CONCAT(D20,F20,I20) -> MAT001013 | D20: MAT | E20: Nệm | F20: 001 | G20: T&N Foam | H20: 24893009852 | I20: 013 | J20: =P20&" x "&Q20&" x "&O20&" cm" -> 160 x 200 x 15 cm | K20: =_xlfn.CONCAT(E20," ",G20," ",J20) -> Nệm T&N Foam 160 x 200 x 15 cm | L20: =_xlfn.XLOOKUP(M20,'0. Mã Supplier'!$B:$B,'0. Mã Supplier'!$C:$C,0) -> SUVN0002 | M20: HAPPYTOWN SLEEPTECH | O20: 15 | P20: 160 | Q20: 200 | R20: 0 | S20: 0 | T20: Roll Carton Box | U20: =P20*10+80 -> 1680 | V20: 370 | W20: 370 | Y20: 5 | AA20: 0 | AB20: 1772300 | AC20: =AB20*1.08 -> 1914084 | AE20: A | AF20: =U20*V20*W20/10^9 -> 0.229992
B21: =D21&F21 -> MAT001 | C21: =_xlfn.CONCAT(D21,F21,I21) -> MAT001014 | D21: MAT | E21: Nệm | F21: 001 | G21: T&N Foam | H21: 24893009852 | I21: 014 | J21: =P21&" x "&Q21&" x "&O21&" cm" -> 180 x 200 x 15 cm | K21: =_xlfn.CONCAT(E21," ",G21," ",J21) -> Nệm T&N Foam 180 x 200 x 15 cm | L21: =_xlfn.XLOOKUP(M21,'0. Mã Supplier'!$B:$B,'0. Mã Supplier'!$C:$C,0) -> SUVN0002 | M21: HAPPYTOWN SLEEPTECH | O21: 15 | P21: 180 | Q21: 200 | R21: 0 | S21: 0 | T21: Roll Carton Box | U21: =P21*10+80 -> 1880 | V21: 370 | W21: 370 | Y21: 5 | AA21: 0 | AB21: 1979600 | AC21: =AB21*1.08 -> 2137968 | AE21: A | AF21: =U21*V21*W21/10^9 -> 0.257372
B22: =D22&F22 -> MAT001 | C22: =_xlfn.CONCAT(D22,F22,I22) -> MAT001015 | D22: MAT | E22: Nệm | F22: 001 | G22: T&N Foam | H22: 24893009852 | I22: 015 | J22: =P22&" x "&Q22&" x "&O22&" cm" -> 200 x 200 x 15 cm | K22: =_xlfn.CONCAT(E22," ",G22," ",J22) -> Nệm T&N Foam 200 x 200 x 15 cm | L22: =_xlfn.XLOOKUP(M22,'0. Mã Supplier'!$B:$B,'0. Mã Supplier'!$C:$C,0) -> SUVN0002 | M22: HAPPYTOWN SLEEPTECH | O22: 15 | P22: 200 | Q22: 200 | R22: 0 | S22: 0 | T22: Roll Carton Box | U22: =P22*10+80 -> 2080 | V22: 370 | W22: 370 | Y22: 5 | AA22: 0 | AB22: 0 | AC22: =AB22*1.08 -> 0 | AE22: A | AF22: =U22*V22*W22/10^9 -> 0.284752
... B31: =D31&F31 -> MAT001 | C31: =_xlfn.CONCAT(D31,F31,I31) -> MAT001024 | D31: MAT | E31: Nệm | F31: 001 | G31: T&N Foam | H31: 24893009852 | I31: 024 | J31: =P31&" x "&Q31&" x "&O31&" cm" -> 200 x 220 x 20 cm | K31: =_xlfn.CONCAT(E31," ",G31," ",J31) -> Nệm T&N Foam 200 x 220 x 20 cm | L31: =_xlfn.XLOOKUP(M31,'0. Mã Supplier'!$B:$B,'0. Mã Supplier'!$C:$C,0) -> SUVN0002 | M31: HAPPYTOWN SLEEPTECH | O31: 20 | P31: 200 | Q31: 220 | R31: 0 | S31: 0 | T31: Roll Carton Box | U31: =P31*10+80 -> 2080 | V31: 370 | W31: 370 | Y31: 5 | AA31: 0 | AB31: 0 | AC31: =AB31*1.08 -> 0 | AE31: A | AF31: =U31*V31*W31/10^9 -> 0.284752
B32: =D32&F32 -> MAT002 | C32: =_xlfn.CONCAT(D32,F32,I32) -> MAT002001 | D32: MAT | E32: Nệm | F32: 002 | G32: Hybrid | H32: 41804007802 | I32: 001 | J32: =P32&" x "&Q32&" x "&O32&" cm" -> 80 x 200 x 25 cm | K32: =_xlfn.CONCAT(E32," ",G32," ",J32) -> Nệm Hybrid 80 x 200 x 25 cm | L32: =_xlfn.XLOOKUP(M32,'0. Mã Supplier'!$B:$B,'0. Mã Supplier'!$C:$C,0) -> SUVN0003 | M32: EVERHOME | O32: 25 | P32: 80 | Q32: 200 | R32: 0 | S32: 0 | T32: Roll Carton Box | V32: 0 | Y32: 5 | AA32: 0 | AB32: 0 | AC32: =AB32*1.08 -> 0 | AE32: A
B33: =D33&F33 -> MAT002 | C33: =_xlfn.CONCAT(D33,F33,I33) -> MAT002002 | D33: MAT | E33: Nệm | F33: 002 | G33: Hybrid | H33: 41804007802 | I33: 002 | J33: =P33&" x "&Q33&" x "&O33&" cm" -> 100 x 200 x 25 cm | K33: =_xlfn.CONCAT(E33," ",G33," ",J33) -> Nệm Hybrid 100 x 200 x 25 cm | L33: =_xlfn.XLOOKUP(M33,'0. Mã Supplier'!$B:$B,'0. Mã Supplier'!$C:$C,0) -> SUVN0003 | M33: EVERHOME | O33: 25 | P33: 100 | Q33: 200 | R33: 0 | S33: 0 | T33: Roll Carton Box | V33: 0 | Y33: 5 | AA33: 0 | AB33: 0 | AC33: =AB33*1.08 -> 0 | AE33: A
B34: =D34&F34 -> MAT002 | C34: =_xlfn.CONCAT(D34,F34,I34) -> MAT002003 | D34: MAT | E34: Nệm | F34: 002 | G34: Hybrid | H34: 41804007802 | I34: 003 | J34: =P34&" x "&Q34&" x "&O34&" cm" -> 120 x 200 x 25 cm | K34: =_xlfn.CONCAT(E34," ",G34," ",J34) -> Nệm Hybrid 120 x 200 x 25 cm | L34: =_xlfn.XLOOKUP(M34,'0. Mã Supplier'!$B:$B,'0. Mã Supplier'!$C:$C,0) -> SUVN0003 | M34: EVERHOME | O34: 25 | P34: 120 | Q34: 200 | R34: 0 | S34: 0 | T34: Roll Carton Box | V34: 0 | Y34: 5 | AA34: 0 | AB34: 1641010 | AC34: =AB34*1.08 -> 1772290.8 | AE34: A
B35: =D35&F35 -> MAT002 | C35: =_xlfn.CONCAT(D35,F35,I35) -> MAT002004 | D35: MAT | E35: Nệm | F35: 002 | G35: Hybrid | H35: 41804007802 | I35: 004 | J35: =P35&" x "&Q35&" x "&O35&" cm" -> 140 x 200 x 25 cm | K35: =_xlfn.CONCAT(E35," ",G35," ",J35) -> Nệm Hybrid 140 x 200 x 25 cm | L35: =_xlfn.XLOOKUP(M35,'0. Mã Supplier'!$B:$B,'0. Mã Supplier'!$C:$C,0) -> SUVN0003 | M35: EVERHOME | O35: 25 | P35: 140 | Q35: 200 | R35: 0 | S35: 0 | T35: Roll Carton Box | V35: 0 | Y35: 5 | AA35: 0 | AB35: 0 | AC35: =AB35*1.08 -> 0 | AE35: A
B36: =D36&F36 -> MAT002 | C36: =_xlfn.CONCAT(D36,F36,I36) -> MAT002005 | D36: MAT | E36: Nệm | F36: 002 | G36: Hybrid | H36: 41804007802 | I36: 005 | J36: =P36&" x "&Q36&" x "&O36&" cm" -> 160 x 200 x 25 cm | K36: =_xlfn.CONCAT(E36," ",G36," ",J36) -> Nệm Hybrid 160 x 200 x 25 cm | L36: =_xlfn.XLOOKUP(M36,'0. Mã Supplier'!$B:$B,'0. Mã Supplier'!$C:$C,0) -> SUVN0003 | M36: EVERHOME | O36: 25 | P36: 160 | Q36: 200 | R36: 0 | S36: 0 | T36: Roll Carton Box | V36: 0 | Y36: 5 | AA36: 0 | AB36: 2229010 | AC36: =AB36*1.08 -> 2407330.8 | AE36: A
B37: =D37&F37 -> MAT002 | C37: =_xlfn.CONCAT(D37,F37,I37) -> MAT002006 | D37: MAT | E37: Nệm | F37: 002 | G37: Hybrid | H37: 41804007802 | I37: 006 | J37: =P37&" x "&Q37&" x "&O37&" cm" -> 180 x 200 x 25 cm | K37: =_xlfn.CONCAT(E37," ",G37," ",J37) -> Nệm Hybrid 180 x 200 x 25 cm | L37: =_xlfn.XLOOKUP(M37,'0. Mã Supplier'!$B:$B,'0. Mã Supplier'!$C:$C,0) -> SUVN0003 | M37: EVERHOME | O37: 25 | P37: 180 | Q37: 200 | R37: 0 | S37: 0 | T37: Roll Carton Box | V37: 0 | Y37: 5 | AA37: 0 | AB37: 2425010 | AC37: =AB37*1.08 -> 2619010.8 | AE37: A
B38: =D38&F38 -> MAT002 | C38: =_xlfn.CONCAT(D38,F38,I38) -> MAT002007 | D38: MAT | E38: Nệm | F38: 002 | G38: Hybrid | H38: 41804007802 | I38: 007 | J38: =P38&" x "&Q38&" x "&O38&" cm" -> 200 x 200 x 25 cm | K38: =_xlfn.CONCAT(E38," ",G38," ",J38) -> Nệm Hybrid 200 x 200 x 25 cm | L38: =_xlfn.XLOOKUP(M38,'0. Mã Supplier'!$B:$B,'0. Mã Supplier'!$C:$C,0) -> SUVN0003 | M38: EVERHOME | O38: 25 | P38: 200 | Q38: 200 | R38: 0 | S38: 0 | T38: Roll Carton Box | V38: 0 | Y38: 5 | AA38: 0 | AB38: 0 | AC38: =AB38*1.08 -> 0 | AE38: A
B39: =D39&F39 -> MAT002 | C39: =_xlfn.CONCAT(D39,F39,I39) -> MAT002008 | D39: MAT | E39: Nệm | F39: 002 | G39: Hybrid | H39: 41804007802 | I39: 008 | J39: =P39&" x "&Q39&" x "&O39&" cm" -> 200 x 220 x 25 cm | K39: =_xlfn.CONCAT(E39," ",G39," ",J39) -> Nệm Hybrid 200 x 220 x 25 cm | L39: =_xlfn.XLOOKUP(M39,'0. Mã Supplier'!$B:$B,'0. Mã Supplier'!$C:$C,0) -> SUVN0003 | M39: EVERHOME | O39: 25 | P39: 200 | Q39: 220 | R39: 0 | S39: 0 | T39: Roll Carton Box | V39: 0 | Y39: 5 | AA39: 0 | AB39: 0 | AC39: =AB39*1.08 -> 0 | AE39: A
B40: =D40&F40 -> MAT003 | C40: =_xlfn.CONCAT(D40,F40,I40) -> MAT003001 | D40: MAT | E40: Nệm | F40: 003 | G40: Hybrid Latex | H40: 43654100667 | I40: 001 | J40: =P40&" x "&Q40&" x "&O40&" cm" -> 80 x 200 x 27 cm | K40: =_xlfn.CONCAT(E40," ",G40," ",J40) -> Nệm Hybrid Latex 80 x 200 x 27 cm | L40: =_xlfn.XLOOKUP(M40,'0. Mã Supplier'!$B:$B,'0. Mã Supplier'!$C:$C,0) -> SUVN0003 | M40: EVERHOME | O40: 27 | P40: 80 | Q40: 200 | R40: 0 | S40: 0 | T40: Roll Carton Box | V40: 0 | Y40: 5 | AA40: 0 | AB40: 0 | AC40: =AB40*1.08 -> 0 | AE40: A
B41: =D41&F41 -> MAT003 | C41: =_xlfn.CONCAT(D41,F41,I41) -> MAT003002 | D41: MAT | E41: Nệm | F41: 003 | G41: Hybrid Latex | H41: 43654100667 | I41: 002 | J41: =P41&" x "&Q41&" x "&O41&" cm" -> 100 x 200 x 27 cm | K41: =_xlfn.CONCAT(E41," ",G41," ",J41) -> Nệm Hybrid Latex 100 x 200 x 27 cm | L41: =_xlfn.XLOOKUP(M41,'0. Mã Supplier'!$B:$B,'0. Mã Supplier'!$C:$C,0) -> SUVN0003 | M41: EVERHOME | O41: 27 | P41: 100 | Q41: 200 | R41: 0 | S41: 0 | T41: Roll Carton Box | V41: 0 | Y41: 5 | AA41: 0 | AB41: 0 | AC41: =AB41*1.08 -> 0 | AE41: A
B42: =D42&F42 -> MAT003 | C42: =_xlfn.CONCAT(D42,F42,I42) -> MAT003003 | D42: MAT | E42: Nệm | F42: 003 | G42: Hybrid Latex | H42: 43654100667 | I42: 003 | J42: =P42&" x "&Q42&" x "&O42&" cm" -> 120 x 200 x 27 cm | K42: =_xlfn.CONCAT(E42," ",G42," ",J42) -> Nệm Hybrid Latex 120 x 200 x 27 cm | L42: =_xlfn.XLOOKUP(M42,'0. Mã Supplier'!$B:$B,'0. Mã Supplier'!$C:$C,0) -> SUVN0003 | M42: EVERHOME | O42: 27 | P42: 120 | Q42: 200 | R42: 0 | S42: 0 | T42: Roll Carton Box | V42: 0 | Y42: 5 | AA42: 0 | AB42: 2082010 | AC42: =AB42*1.08 -> 2248570.8 | AE42: A
B43: =D43&F43 -> MAT003 | C43: =_xlfn.CONCAT(D43,F43,I43) -> MAT003004 | D43: MAT | E43: Nệm | F43: 003 | G43: Hybrid Latex | H43: 43654100667 | I43: 004 | J43: =P43&" x "&Q43&" x "&O43&" cm" -> 140 x 200 x 27 cm | K43: =_xlfn.CONCAT(E43," ",G43," ",J43) -> Nệm Hybrid Latex 140 x 200 x 27 cm | L43: =_xlfn.XLOOKUP(M43,'0. Mã Supplier'!$B:$B,'0. Mã Supplier'!$C:$C,0) -> SUVN0003 | M43: EVERHOME | O43: 27 | P43: 140 | Q43: 200 | R43: 0 | S43: 0 | T43: Roll Carton Box | V43: 0 | Y43: 5 | AA43: 0 | AB43: 0 | AC43: =AB43*1.08 -> 0 | AE43: A
... B49: =D49&F49 -> MAT004 | C49: =_xlfn.CONCAT(D49,F49,I49) -> MAT004002 | D49: MAT | E49: Nệm | F49: 004 | G49: Power X Core | H49: 42770983649 | I49: 002 | J49: =P49&" x "&Q49&" x "&O49&" cm" -> 100 x 200 x 15 cm | K49: =_xlfn.CONCAT(E49," ",G49," ",J49) -> Nệm Power X Core 100 x 200 x 15 cm | L49: =_xlfn.XLOOKUP(M49,'0. Mã Supplier'!$B:$B,'0. Mã Supplier'!$C:$C,0) -> SUCN0001 | M49: POWER X | O49: 15 | P49: 100 | Q49: 200 | R49: 0 | S49: 0 | T49: Roll Carton Box | V49: 0 | Y49: 5 | AA49: 0 | AB49: 0 | AC49: =AB49*1.08 -> 0 | AE49: A
B50: =D50&F50 -> MAT004 | C50: =_xlfn.CONCAT(D50,F50,I50) -> MAT004003 | D50: MAT | E50: Nệm | F50: 004 | G50: Power X Core | H50: 42770983649 | I50: 003 | J50: =P50&" x "&Q50&" x "&O50&" cm" -> 120 x 200 x 15 cm | K50: =_xlfn.CONCAT(E50," ",G50," ",J50) -> Nệm Power X Core 120 x 200 x 15 cm | L50: =_xlfn.XLOOKUP(M50,'0. Mã Supplier'!$B:$B,'0. Mã Supplier'!$C:$C,0) -> SUCN0001 | M50: POWER X | O50: 15 | P50: 120 | Q50: 200 | R50: 12 | S50: 13 | T50: Roll Carton Box | U50: 128 | V50: 25 | W50: 25 | Y50: 5 | AA50: 55.2 | AB50: 1527869 | AC50: =AB50*1.08 -> 1650098.5 | AE50: A
B51: =D51&F51 -> MAT004 | C51: =_xlfn.CONCAT(D51,F51,I51) -> MAT004004 | D51: MAT | E51: Nệm | F51: 004 | G51: Power X Core | H51: 42770983649 | I51: 004 | J51: =P51&" x "&Q51&" x "&O51&" cm" -> 140 x 200 x 15 cm | K51: =_xlfn.CONCAT(E51," ",G51," ",J51) -> Nệm Power X Core 140 x 200 x 15 cm | L51: =_xlfn.XLOOKUP(M51,'0. Mã Supplier'!$B:$B,'0. Mã Supplier'!$C:$C,0) -> SUCN0001 | M51: POWER X | O51: 15 | P51: 140 | Q51: 200 | R51: 14 | S51: 15 | T51: Roll Carton Box | U51: 148 | V51: 25 | W51: 25 | Y51: 5 | AA51: 62 | AB51: 1719112 | AC51: =AB51*1.08 -> 1856641 | AE51: A
B52: =D52&F52 -> MAT004 | C52: =_xlfn.CONCAT(D52,F52,I52) -> MAT004005 | D52: MAT | E52: Nệm | F52: 004 | G52: Power X Core | H52: 42770983649 | I52: 005 | J52: =P52&" x "&Q52&" x "&O52&" cm" -> 160 x 200 x 15 cm | K52: =_xlfn.CONCAT(E52," ",G52," ",J52) -> Nệm Power X Core 160 x 200 x 15 cm | L52: =_xlfn.XLOOKUP(M52,'0. Mã Supplier'!$B:$B,'0. Mã Supplier'!$C:$C,0) -> SUCN0001 | M52: POWER X | O52: 15 | P52: 160 | Q52: 200 | R52: 16.982143 | S52: 18 | T52: Roll Carton Box | U52: 168 | V52: 25 | W52: 25 | Y52: 5 | AA52: 68.5 | AB52: 1902549.1 | AC52: =AB52*1.08 -> 2054753 | AE52: A
B53: =D53&F53 -> MAT004 | C53: =_xlfn.CONCAT(D53,F53,I53) -> MAT004006 | D53: MAT | E53: Nệm | F53: 004 | G53: Power X Core | H53: 42770983649 | I53: 006 | J53: =P53&" x "&Q53&" x "&O53&" cm" -> 180 x 200 x 15 cm | K53: =_xlfn.CONCAT(E53," ",G53," ",J53) -> Nệm Power X Core 180 x 200 x 15 cm | L53: =_xlfn.XLOOKUP(M53,'0. Mã Supplier'!$B:$B,'0. Mã Supplier'!$C:$C,0) -> SUCN0001 | M53: POWER X | O53: 15 | P53: 180 | Q53: 200 | R53: 19 | S53: 20.5 | T53: Roll Carton Box | U53: 188 | V53: 25 | W53: 25 | Y53: 5 | AA53: 75 | AB53: 2085986.1 | AC53: =AB53*1.08 -> 2252865 | AE53: A
B54: =D54&F54 -> MAT004 | C54: =_xlfn.CONCAT(D54,F54,I54) -> MAT004007 | D54: MAT | E54: Nệm | F54: 004 | G54: Power X Core | H54: 42770983649 | I54: 007 | J54: =P54&" x "&Q54&" x "&O54&" cm" -> 200 x 200 x 15 cm | K54: =_xlfn.CONCAT(E54," ",G54," ",J54) -> Nệm Power X Core 200 x 200 x 15 cm | L54: =_xlfn.XLOOKUP(M54,'0. Mã Supplier'!$B:$B,'0. Mã Supplier'!$C:$C,0) -> SUCN0001 | M54: POWER X | O54: 15 | P54: 200 | Q54: 200 | R54: 0 | S54: 0 | T54: Roll Carton Box | U54: 208 | V54: 25 | W54: 25 | Y54: 5 | AA54: 0 | AB54: 0 | AC54: =AB54*1.08 -> 0 | AE54: A
B55: =D55&F55 -> MAT004 | C55: =_xlfn.CONCAT(D55,F55,I55) -> MAT004008 | D55: MAT | E55: Nệm | F55: 004 | G55: Power X Core | H55: 42770983649 | I55: 008 | J55: =P55&" x "&Q55&" x "&O55&" cm" -> 200 x 220 x 15 cm | K55: =_xlfn.CONCAT(E55," ",G55," ",J55) -> Nệm Power X Core 200 x 220 x 15 cm | L55: =_xlfn.XLOOKUP(M55,'0. Mã Supplier'!$B:$B,'0. Mã Supplier'!$C:$C,0) -> SUCN0001 | M55: POWER X | O55: 15 | P55: 200 | Q55: 220 | R55: 20 | S55: 22 | T55: Roll Carton Box | U55: 208 | V55: 25 | W55: 25 | Y55: 5 | AA55: 87.13 | AB55: 2415915.7 | AC55: =AB55*1.08 -> 2609189 | AE55: A
B56: =D56&F56 -> MAT005 | C56: =_xlfn.CONCAT(D56,F56,I56) -> MAT005001 | D56: MAT | E56: Nệm | F56: 005 | G56: Power X Flow | H56: 41970997159 | I56: 001 | J56: =P56&" x "&Q56&" x "&O56&" cm" -> 80 x 200 x 22 cm | K56: =_xlfn.CONCAT(E56," ",G56," ",J56) -> Nệm Power X Flow 80 x 200 x 22 cm | L56: =_xlfn.XLOOKUP(M56,'0. Mã Supplier'!$B:$B,'0. Mã Supplier'!$C:$C,0) -> SUCN0001 | M56: POWER X | O56: 22 | P56: 80 | Q56: 200 | R56: 0 | S56: 0 | T56: Roll Carton Box | V56: 0 | Y56: 5 | AA56: 0 | AB56: 0 | AC56: =AB56*1.08 -> 0 | AE56: A
...

Sheet 4. Purchasing
A1: PO | B1: Code | C1: Product Description | D1: Supplier code | E1: Supplier | F1: Unit | G1: Qty order | H1: Qty confirm | I1: Cost | J1: Total Cost | K1: Total Cost (VAT) | L1: Date Request | M1: Date Supply confirm | N1: Date Receive | O1: Leadtime | P1: Month | Q1: Year | R1: Goods receipt status | S1: Note | T1: Invoice Date | U1: Payment Terms | V1: Due Date | W1: Due Week | X1: Due Month | Y1: Due Year | Z1: Payment status | AA1: Days Overdue | AB1: Paid Amount | AC1: Payment Date | AD1: Outstanding Amount
A2: PWX-001 | B2: MAT004003 | C2: =VLOOKUP(B2,'1. Master Data'!$C:$K,9,0) -> Nệm Power X Core 120 x 200 x 15 cm | E2: POWER X | F2: Cái | G2: 10 | H2: 10 | I2: =VLOOKUP($B2,'1. Master Data'!$C:$AB,26,0) -> 1527869 | J2: =I2*H2 -> 15278690 | K2: =J2*1.08 -> 16500985 | N2: 45879 | O2: =N2-L2 -> 45879 | P2: =MONTH(N2) -> 8 | Q2: =YEAR(N2) -> 2025 | R2: Nhập kho | T2: 45887 | U2: =VLOOKUP($E2,'0. Mã Supplier'!$B:$F,5,0) -> 180 | V2: =T2+U2 -> 46067 | W2: =WEEKNUM(V2) -> 7 | X2: =IF(V2<>0,MONTH(V2),"") -> 2 | Y2: =YEAR(V2) -> 2026 | AA2: =IF(Z2="yes",0,TODAY()-V2) -> 197 | AB2: =IF(Z2="Yes",K2) -> FALSE | AD2: =IFERROR(K2-AB2,0) -> 16500985
A3: PWX-001 | B3: MAT004004 | C3: =VLOOKUP(B3,'1. Master Data'!$C:$K,9,0) -> Nệm Power X Core 140 x 200 x 15 cm | E3: POWER X | F3: Cái | G3: 4 | H3: 4 | I3: =VLOOKUP($B3,'1. Master Data'!$C:$AB,26,0) -> 1719112 | J3: =I3*H3 -> 6876448.1 | K3: =J3*1.08 -> 7426564 | N3: 45879 | O3: =N3-L3 -> 45879 | P3: =MONTH(N3) -> 8 | Q3: =YEAR(N3) -> 2025 | R3: Nhập kho | T3: 45887 | U3: =VLOOKUP($E3,'0. Mã Supplier'!$B:$F,5,0) -> 180 | V3: =T3+U3 -> 46067 | W3: =WEEKNUM(V3) -> 7 | X3: =IF(V3<>0,MONTH(V3),"") -> 2 | Y3: =YEAR(V3) -> 2026 | AA3: =IF(Z3="yes",0,TODAY()-V3) -> 197 | AB3: =IF(Z3="Yes",K3) -> FALSE | AD3: =IFERROR(K3-AB3,0) -> 7426564
A4: PWX-001 | B4: MAT004005 | C4: =VLOOKUP(B4,'1. Master Data'!$C:$K,9,0) -> Nệm Power X Core 160 x 200 x 15 cm | E4: POWER X | F4: Cái | G4: 56 | H4: 56 | I4: =VLOOKUP($B4,'1. Master Data'!$C:$AB,26,0) -> 1902549.1 | J4: =I4*H4 -> 1.0654275e+08 | K4: =J4*1.08 -> 1.1506617e+08 | N4: 45879 | O4: =N4-L4 -> 45879 | P4: =MONTH(N4) -> 8 | Q4: =YEAR(N4) -> 2025 | R4: Nhập kho | T4: 45887 | U4: =VLOOKUP($E4,'0. Mã Supplier'!$B:$F,5,0) -> 180 | V4: =T4+U4 -> 46067 | W4: =WEEKNUM(V4) -> 7 | X4: =IF(V4<>0,MONTH(V4),"") -> 2 | Y4: =YEAR(V4) -> 2026 | AA4: =IF(Z4="yes",0,TODAY()-V4) -> 197 | AB4: =IF(Z4="Yes",K4) -> FALSE | AD4: =IFERROR(K4-AB4,0) -> 1.1506617e+08
A5: PWX-001 | B5: MAT004006 | C5: =VLOOKUP(B5,'1. Master Data'!$C:$K,9,0) -> Nệm Power X Core 180 x 200 x 15 cm | E5: POWER X | F5: Cái | G5: 44 | H5: 44 | I5: =VLOOKUP($B5,'1. Master Data'!$C:$AB,26,0) -> 2085986.1 | J5: =I5*H5 -> 91783388 | K5: =J5*1.08 -> 99126059 | N5: 45879 | O5: =N5-L5 -> 45879 | P5: =MONTH(N5) -> 8 | Q5: =YEAR(N5) -> 2025 | R5: Nhập kho | T5: 45887 | U5: =VLOOKUP($E5,'0. Mã Supplier'!$B:$F,5,0) -> 180 | V5: =T5+U5 -> 46067 | W5: =WEEKNUM(V5) -> 7 | X5: =IF(V5<>0,MONTH(V5),"") -> 2 | Y5: =YEAR(V5) -> 2026 | AA5: =IF(Z5="yes",0,TODAY()-V5) -> 197 | AB5: =IF(Z5="Yes",K5) -> FALSE | AD5: =IFERROR(K5-AB5,0) -> 99126059
A6: PWX-001 | B6: MAT004008 | C6: =VLOOKUP(B6,'1. Master Data'!$C:$K,9,0) -> Nệm Power X Core 200 x 220 x 15 cm | E6: POWER X | F6: Cái | G6: 6 | H6: 6 | I6: =VLOOKUP($B6,'1. Master Data'!$C:$AB,26,0) -> 2415915.7 | J6: =I6*H6 -> 14495494 | K6: =J6*1.08 -> 15655134 | N6: 45879 | O6: =N6-L6 -> 45879 | P6: =MONTH(N6) -> 8 | Q6: =YEAR(N6) -> 2025 | R6: Nhập kho | T6: 45887 | U6: =VLOOKUP($E6,'0. Mã Supplier'!$B:$F,5,0) -> 180 | V6: =T6+U6 -> 46067 | W6: =WEEKNUM(V6) -> 7 | X6: =IF(V6<>0,MONTH(V6),"") -> 2 | Y6: =YEAR(V6) -> 2026 | AA6: =IF(Z6="yes",0,TODAY()-V6) -> 197 | AB6: =IF(Z6="Yes",K6) -> FALSE | AD6: =IFERROR(K6-AB6,0) -> 15655134
A7: PWX-001 | B7: MAT004005 | C7: =VLOOKUP(B7,'1. Master Data'!$C:$K,9,0) -> Nệm Power X Core 160 x 200 x 15 cm | E7: POWER X | F7: Cái | G7: 1 | H7: 1 | I7: =VLOOKUP($B7,'1. Master Data'!$C:$AB,26,0) -> 1902549.1 | J7: =I7*H7 -> 1902549.1 | K7: =J7*1.08 -> 2054753 | N7: 45879 | O7: =N7-L7 -> 45879 | P7: =MONTH(N7) -> 8 | Q7: =YEAR(N7) -> 2025 | R7: Nhập kho | T7: 45887 | U7: =VLOOKUP($E7,'0. Mã Supplier'!$B:$F,5,0) -> 180 | V7: =T7+U7 -> 46067 | W7: =WEEKNUM(V7) -> 7 | X7: =IF(V7<>0,MONTH(V7),"") -> 2 | Y7: =YEAR(V7) -> 2026 | AA7: =IF(Z7="yes",0,TODAY()-V7) -> 197 | AB7: =IF(Z7="Yes",K7) -> FALSE | AD7: =IFERROR(K7-AB7,0) -> 2054753
A8: PWX-001 | B8: MAT005003 | C8: =VLOOKUP(B8,'1. Master Data'!$C:$K,9,0) -> Nệm Power X Flow 120 x 200 x 22 cm | E8: POWER X | F8: Cái | G8: 1 | H8: 1 | I8: =VLOOKUP($B8,'1. Master Data'!$C:$AB,26,0) -> 2135393.6 | J8: =I8*H8 -> 2135393.6 | K8: =J8*1.08 -> 2306225.1 | N8: 45879 | O8: =N8-L8 -> 45879 | P8: =MONTH(N8) -> 8 | Q8: =YEAR(N8) -> 2025 | R8: Nhập kho | T8: 45887 | U8: =VLOOKUP($E8,'0. Mã Supplier'!$B:$F,5,0) -> 180 | V8: =T8+U8 -> 46067 | W8: =WEEKNUM(V8) -> 7 | X8: =IF(V8<>0,MONTH(V8),"") -> 2 | Y8: =YEAR(V8) -> 2026 | AA8: =IF(Z8="yes",0,TODAY()-V8) -> 197 | AB8: =IF(Z8="Yes",K8) -> FALSE | AD8: =IFERROR(K8-AB8,0) -> 2306225.1
A9: PWX-001 | B9: MAT005004 | C9: =VLOOKUP(B9,'1. Master Data'!$C:$K,9,0) -> Nệm Power X Flow 140 x 200 x 22 cm | E9: POWER X | F9: Cái | G9: 1 | H9: 1 | I9: =VLOOKUP($B9,'1. Master Data'!$C:$AB,26,0) -> 2416195.7 | J9: =I9*H9 -> 2416195.7 | K9: =J9*1.08 -> 2609491.4 | N9: 45879 | O9: =N9-L9 -> 45879 | P9: =MONTH(N9) -> 8 | Q9: =YEAR(N9) -> 2025 | R9: Nhập kho | T9: 45887 | U9: =VLOOKUP($E9,'0. Mã Supplier'!$B:$F,5,0) -> 180 | V9: =T9+U9 -> 46067 | W9: =WEEKNUM(V9) -> 7 | X9: =IF(V9<>0,MONTH(V9),"") -> 2 | Y9: =YEAR(V9) -> 2026 | AA9: =IF(Z9="yes",0,TODAY()-V9) -> 197 | AB9: =IF(Z9="Yes",K9) -> FALSE | AD9: =IFERROR(K9-AB9,0) -> 2609491.4
A10: PWX-001 | B10: MAT005005 | C10: =VLOOKUP(B10,'1. Master Data'!$C:$K,9,0) -> Nệm Power X Flow 160 x 200 x 22 cm | E10: POWER X | F10: Cái | G10: 28 | H10: 28 | I10: =VLOOKUP($B10,'1. Master Data'!$C:$AB,26,0) -> 2696997.8 | J10: =I10*H10 -> 75515940 | K10: =J10*1.08 -> 81557215 | N10: 45879 | O10: =N10-L10 -> 45879 | P10: =MONTH(N10) -> 8 | Q10: =YEAR(N10) -> 2025 | R10: Nhập kho | T10: 45887 | U10: =VLOOKUP($E10,'0. Mã Supplier'!$B:$F,5,0) -> 180 | V10: =T10+U10 -> 46067 | W10: =WEEKNUM(V10) -> 7 | X10: =IF(V10<>0,MONTH(V10),"") -> 2 | Y10: =YEAR(V10) -> 2026 | AA10: =IF(Z10="yes",0,TODAY()-V10) -> 197 | AB10: =IF(Z10="Yes",K10) -> FALSE | AD10: =IFERROR(K10-AB10,0) -> 81557215
A11: PWX-001 | B11: MAT005006 | C11: =VLOOKUP(B11,'1. Master Data'!$C:$K,9,0) -> Nệm Power X Flow 180 x 200 x 22 cm | E11: POWER X | F11: Cái | G11: 25 | H11: 25 | I11: =VLOOKUP($B11,'1. Master Data'!$C:$AB,26,0) -> 2951780 | J11: =I11*H11 -> 73794499 | K11: =J11*1.08 -> 79698059 | N11: 45879 | O11: =N11-L11 -> 45879 | P11: =MONTH(N11) -> 8 | Q11: =YEAR(N11) -> 2025 | R11: Nhập kho | T11: 45887 | U11: =VLOOKUP($E11,'0. Mã Supplier'!$B:$F,5,0) -> 180 | V11: =T11+U11 -> 46067 | W11: =WEEKNUM(V11) -> 7 | X11: =IF(V11<>0,MONTH(V11),"") -> 2 | Y11: =YEAR(V11) -> 2026 | AA11: =IF(Z11="yes",0,TODAY()-V11) -> 197 | AB11: =IF(Z11="Yes",K11) -> FALSE | AD11: =IFERROR(K11-AB11,0) -> 79698059
A12: PWX-001 | B12: MAT005008 | C12: =VLOOKUP(B12,'1. Master Data'!$C:$K,9,0) -> Nệm Power X Flow 200 x 220 x 22 cm | E12: POWER X | F12: Cái | G12: 5 | H12: 5 | I12: =VLOOKUP($B12,'1. Master Data'!$C:$AB,26,0) -> 3367365.7 | J12: =I12*H12 -> 16836828 | K12: =J12*1.08 -> 18183775 | N12: 45879 | O12: =N12-L12 -> 45879 | P12: =MONTH(N12) -> 8 | Q12: =YEAR(N12) -> 2025 | R12: Nhập kho | T12: 45887 | U12: =VLOOKUP($E12,'0. Mã Supplier'!$B:$F,5,0) -> 180 | V12: =T12+U12 -> 46067 | W12: =WEEKNUM(V12) -> 7 | X12: =IF(V12<>0,MONTH(V12),"") -> 2 | Y12: =YEAR(V12) -> 2026 | AA12: =IF(Z12="yes",0,TODAY()-V12) -> 197 | AB12: =IF(Z12="Yes",K12) -> FALSE | AD12: =IFERROR(K12-AB12,0) -> 18183775
A13: PWX-001 | B13: MAT005005 | C13: =VLOOKUP(B13,'1. Master Data'!$C:$K,9,0) -> Nệm Power X Flow 160 x 200 x 22 cm | E13: POWER X | F13: Cái | G13: 1 | H13: 1 | I13: =VLOOKUP($B13,'1. Master Data'!$C:$AB,26,0) -> 2696997.8 | J13: =I13*H13 -> 2696997.8 | K13: =J13*1.08 -> 2912757.7 | N13: 45879 | O13: =N13-L13 -> 45879 | P13: =MONTH(N13) -> 8 | Q13: =YEAR(N13) -> 2025 | R13: Nhập kho | T13: 45887 | U13: =VLOOKUP($E13,'0. Mã Supplier'!$B:$F,5,0) -> 180 | V13: =T13+U13 -> 46067 | W13: =WEEKNUM(V13) -> 7 | X13: =IF(V13<>0,MONTH(V13),"") -> 2 | Y13: =YEAR(V13) -> 2026 | AA13: =IF(Z13="yes",0,TODAY()-V13) -> 197 | AB13: =IF(Z13="Yes",K13) -> FALSE | AD13: =IFERROR(K13-AB13,0) -> 2912757.7
... A27: PWX-001 | B27: PIL003001 | C27: =VLOOKUP(B27,'1. Master Data'!$C:$K,9,0) -> Gối Power X Matrix 40 x 60 x 12 cm | E27: POWER X | F27: Cái | G27: 50 | H27: 50 | I27: =VLOOKUP($B27,'1. Master Data'!$C:$AB,26,0) -> 473497.38 | J27: =I27*H27 -> 23674869 | K27: =J27*1.08 -> 25568858 | N27: 45879 | O27: =N27-L27 -> 45879 | P27: =MONTH(N27) -> 8 | Q27: =YEAR(N27) -> 2025 | R27: Nhập kho | T27: 45887 | U27: =VLOOKUP($E27,'0. Mã Supplier'!$B:$F,5,0) -> 180 | V27: =T27+U27 -> 46067 | W27: =WEEKNUM(V27) -> 7 | X27: =IF(V27<>0,MONTH(V27),"") -> 2 | Y27: =YEAR(V27) -> 2026 | AA27: =IF(Z27="yes",0,TODAY()-V27) -> 197 | AB27: =IF(Z27="Yes",K27) -> FALSE | AD27: =IFERROR(K27-AB27,0) -> 25568858
A28: HHN-001 | B28: BLA002001 | C28: =VLOOKUP(B28,'1. Master Data'!$C:$K,9,0) -> Chăn Tencel 60s Xanh dương pastel 200 x 230 cm | D28: =VLOOKUP(E28,'0. Mã Supplier'!$B:$C,2,0) -> SUVN0001 | E28: HUY HOÀNG NAM | F28: Cái | G28: 4 | H28: 4 | I28: =VLOOKUP($B28,'1. Master Data'!$C:$AB,26,0) -> 429000 | J28: =I28*H28 -> 1716000 | K28: =J28*1.08 -> 1853280 | N28: 45658 | O28: =N28-L28 -> 45658 | P28: =MONTH(N28) -> 1 | Q28: =YEAR(N28) -> 2025 | R28: Nhập kho | T28: 45709 | U28: =VLOOKUP($E28,'0. Mã Supplier'!$B:$F,5,0) -> 0 | V28: =T28+U28 -> 45709 | W28: =WEEKNUM(V28) -> 8 | X28: =IF(V28<>0,MONTH(V28),"") -> 2 | Y28: =YEAR(V28) -> 2025 | Z28: Yes | AA28: =IF(Z28="yes",0,TODAY()-V28) -> 0 | AB28: =IF(Z28="Yes",K28) -> 1853280 | AD28: =IFERROR(K28-AB28,0) -> 0
A29: HHN-001 | B29: BLA002002 | C29: =VLOOKUP(B29,'1. Master Data'!$C:$K,9,0) -> Chăn Tencel 60s Hồng pastel 200 x 230 cm | D29: =VLOOKUP(E29,'0. Mã Supplier'!$B:$C,2,0) -> SUVN0001 | E29: HUY HOÀNG NAM | F29: Cái | G29: 7 | H29: 7 | I29: =VLOOKUP($B29,'1. Master Data'!$C:$AB,26,0) -> 429000 | J29: =I29*H29 -> 3003000 | K29: =J29*1.08 -> 3243240 | N29: 45658 | O29: =N29-L29 -> 45658 | P29: =MONTH(N29) -> 1 | Q29: =YEAR(N29) -> 2025 | R29: Nhập kho | T29: 45709 | U29: =VLOOKUP($E29,'0. Mã Supplier'!$B:$F,5,0) -> 0 | V29: =T29+U29 -> 45709 | W29: =WEEKNUM(V29) -> 8 | X29: =IF(V29<>0,MONTH(V29),"") -> 2 | Y29: =YEAR(V29) -> 2025 | Z29: Yes | AA29: =IF(Z29="yes",0,TODAY()-V29) -> 0 | AB29: =IF(Z29="Yes",K29) -> 3243240 | AD29: =IFERROR(K29-AB29,0) -> 0
A30: HHN-001 | B30: BLA002003 | C30: =VLOOKUP(B30,'1. Master Data'!$C:$K,9,0) -> Chăn Tencel 60s Xanh rêu pastel 200 x 230 cm | D30: =VLOOKUP(E30,'0. Mã Supplier'!$B:$C,2,0) -> SUVN0001 | E30: HUY HOÀNG NAM | F30: Cái | G30: 1 | H30: 1 | I30: =VLOOKUP($B30,'1. Master Data'!$C:$AB,26,0) -> 429000 | J30: =I30*H30 -> 429000 | K30: =J30*1.08 -> 463320 | N30: 45658 | O30: =N30-L30 -> 45658 | P30: =MONTH(N30) -> 1 | Q30: =YEAR(N30) -> 2025 | R30: Nhập kho | T30: 45709 | U30: =VLOOKUP($E30,'0. Mã Supplier'!$B:$F,5,0) -> 0 | V30: =T30+U30 -> 45709 | W30: =WEEKNUM(V30) -> 8 | X30: =IF(V30<>0,MONTH(V30),"") -> 2 | Y30: =YEAR(V30) -> 2025 | Z30: Yes | AA30: =IF(Z30="yes",0,TODAY()-V30) -> 0 | AB30: =IF(Z30="Yes",K30) -> 463320 | AD30: =IFERROR(K30-AB30,0) -> 0
A31: HHN-001 | B31: BLA002004 | C31: =VLOOKUP(B31,'1. Master Data'!$C:$K,9,0) -> Chăn Tencel 60s Hồng trắng pastel 200 x 230 cm | D31: =VLOOKUP(E31,'0. Mã Supplier'!$B:$C,2,0) -> SUVN0001 | E31: HUY HOÀNG NAM | F31: Cái | G31: 1 | H31: 1 | I31: =VLOOKUP($B31,'1. Master Data'!$C:$AB,26,0) -> 429000 | J31: =I31*H31 -> 429000 | K31: =J31*1.08 -> 463320 | N31: 45658 | O31: =N31-L31 -> 45658 | P31: =MONTH(N31) -> 1 | Q31: =YEAR(N31) -> 2025 | R31: Nhập kho | T31: 45709 | U31: =VLOOKUP($E31,'0. Mã Supplier'!$B:$F,5,0) -> 0 | V31: =T31+U31 -> 45709 | W31: =WEEKNUM(V31) -> 8 | X31: =IF(V31<>0,MONTH(V31),"") -> 2 | Y31: =YEAR(V31) -> 2025 | Z31: Yes | AA31: =IF(Z31="yes",0,TODAY()-V31) -> 0 | AB31: =IF(Z31="Yes",K31) -> 463320 | AD31: =IFERROR(K31-AB31,0) -> 0
A32: HHN-001 | B32: BLA002005 | C32: =VLOOKUP(B32,'1. Master Data'!$C:$K,9,0) -> Chăn Tencel 60s Xám lông chuột 200 x 230 cm | D32: =VLOOKUP(E32,'0. Mã Supplier'!$B:$C,2,0) -> SUVN0001 | E32: HUY HOÀNG NAM | F32: Cái | G32: 1 | H32: 1 | I32: =VLOOKUP($B32,'1. Master Data'!$C:$AB,26,0) -> 429000 | J32: =I32*H32 -> 429000 | K32: =J32*1.08 -> 463320 | N32: 45658 | O32: =N32-L32 -> 45658 | P32: =MONTH(N32) -> 1 | Q32: =YEAR(N32) -> 2025 | R32: Nhập kho | T32: 45709 | U32: =VLOOKUP($E32,'0. Mã Supplier'!$B:$F,5,0) -> 0 | V32: =T32+U32 -> 45709 | W32: =WEEKNUM(V32) -> 8 | X32: =IF(V32<>0,MONTH(V32),"") -> 2 | Y32: =YEAR(V32) -> 2025 | Z32: Yes | AA32: =IF(Z32="yes",0,TODAY()-V32) -> 0 | AB32: =IF(Z32="Yes",K32) -> 463320 | AD32: =IFERROR(K32-AB32,0) -> 0
A33: HHN-001 | B33: BLA002006 | C33: =VLOOKUP(B33,'1. Master Data'!$C:$K,9,0) -> Chăn Tencel 60s Xám xanh dương 200 x 230 cm | D33: =VLOOKUP(E33,'0. Mã Supplier'!$B:$C,2,0) -> SUVN0001 | E33: HUY HOÀNG NAM | F33: Cái | G33: 6 | H33: 6 | I33: =VLOOKUP($B33,'1. Master Data'!$C:$AB,26,0) -> 429000 | J33: =I33*H33 -> 2574000 | K33: =J33*1.08 -> 2779920 | N33: 45658 | O33: =N33-L33 -> 45658 | P33: =MONTH(N33) -> 1 | Q33: =YEAR(N33) -> 2025 | R33: Nhập kho | T33: 45709 | U33: =VLOOKUP($E33,'0. Mã Supplier'!$B:$F,5,0) -> 0 | V33: =T33+U33 -> 45709 | W33: =WEEKNUM(V33) -> 8 | X33: =IF(V33<>0,MONTH(V33),"") -> 2 | Y33: =YEAR(V33) -> 2025 | Z33: Yes | AA33: =IF(Z33="yes",0,TODAY()-V33) -> 0 | AB33: =IF(Z33="Yes",K33) -> 2779920 | AD33: =IFERROR(K33-AB33,0) -> 0
A34: HHN-001 | B34: BLA001001 | C34: =VLOOKUP(B34,'1. Master Data'!$C:$K,9,0) -> Chăn Lạnh 4.8 Xanh dương pastel 200 x 230 cm, Vải cooling mát lạnh | D34: =VLOOKUP(E34,'0. Mã Supplier'!$B:$C,2,0) -> SUVN0001 | E34: HUY HOÀNG NAM | F34: Cái | G34: 5 | H34: 5 | I34: =VLOOKUP($B34,'1. Master Data'!$C:$AB,26,0) -> 280000 | J34: =I34*H34 -> 1400000 | K34: =J34*1.08 -> 1512000 | N34: 45658 | O34: =N34-L34 -> 45658 | P34: =MONTH(N34) -> 1 | Q34: =YEAR(N34) -> 2025 | R34: Nhập kho | T34: 45709 | U34: =VLOOKUP($E34,'0. Mã Supplier'!$B:$F,5,0) -> 0 | V34: =T34+U34 -> 45709 | W34: =WEEKNUM(V34) -> 8 | X34: =IF(V34<>0,MONTH(V34),"") -> 2 | Y34: =YEAR(V34) -> 2025 | Z34: Yes | AA34: =IF(Z34="yes",0,TODAY()-V34) -> 0 | AB34: =IF(Z34="Yes",K34) -> 1512000 | AD34: =IFERROR(K34-AB34,0) -> 0
A35: HHN-001 | B35: BLA001002 | C35: =VLOOKUP(B35,'1. Master Data'!$C:$K,9,0) -> Chăn Lạnh 4.8 Xám pastel 200 x 230 cm, Vải cooling mát lạnh | D35: =VLOOKUP(E35,'0. Mã Supplier'!$B:$C,2,0) -> SUVN0001 | E35: HUY HOÀNG NAM | F35: Cái | G35: 3 | H35: 3 | I35: =VLOOKUP($B35,'1. Master Data'!$C:$AB,26,0) -> 280000 | J35: =I35*H35 -> 840000 | K35: =J35*1.08 -> 907200 | N35: 45658 | O35: =N35-L35 -> 45658 | P35: =MONTH(N35) -> 1 | Q35: =YEAR(N35) -> 2025 | R35: Nhập kho | T35: 45709 | U35: =VLOOKUP($E35,'0. Mã Supplier'!$B:$F,5,0) -> 0 | V35: =T35+U35 -> 45709 | W35: =WEEKNUM(V35) -> 8 | X35: =IF(V35<>0,MONTH(V35),"") -> 2 | Y35: =YEAR(V35) -> 2025 | Z35: Yes | AA35: =IF(Z35="yes",0,TODAY()-V35) -> 0 | AB35: =IF(Z35="Yes",K35) -> 907200 | AD35: =IFERROR(K35-AB35,0) -> 0
A36: HHN-001 | B36: BLA001003 | C36: =VLOOKUP(B36,'1. Master Data'!$C:$K,9,0) -> Chăn Lạnh 4.8 Tím hoa cà 200 x 230 cm, Vải cooling mát lạnh | D36: =VLOOKUP(E36,'0. Mã Supplier'!$B:$C,2,0) -> SUVN0001 | E36: HUY HOÀNG NAM | F36: Cái | G36: 7 | H36: 7 | I36: =VLOOKUP($B36,'1. Master Data'!$C:$AB,26,0) -> 280000 | J36: =I36*H36 -> 1960000 | K36: =J36*1.08 -> 2116800 | N36: 45658 | O36: =N36-L36 -> 45658 | P36: =MONTH(N36) -> 1 | Q36: =YEAR(N36) -> 2025 | R36: Nhập kho | T36: 45709 | U36: =VLOOKUP($E36,'0. Mã Supplier'!$B:$F,5,0) -> 0 | V36: =T36+U36 -> 45709 | W36: =WEEKNUM(V36) -> 8 | X36: =IF(V36<>0,MONTH(V36),"") -> 2 | Y36: =YEAR(V36) -> 2025 | Z36: Yes | AA36: =IF(Z36="yes",0,TODAY()-V36) -> 0 | AB36: =IF(Z36="Yes",K36) -> 2116800 | AD36: =IFERROR(K36-AB36,0) -> 0
A37: HHN-001 | B37: BLA001005 | C37: =VLOOKUP(B37,'1. Master Data'!$C:$K,9,0) -> Chăn Lạnh 4.8 Xanh dương xám 200 x 230 cm, Vải cooling mát lạnh | D37: =VLOOKUP(E37,'0. Mã Supplier'!$B:$C,2,0) -> SUVN0001 | E37: HUY HOÀNG NAM | F37: Cái | G37: 1 | H37: 1 | I37: =VLOOKUP($B37,'1. Master Data'!$C:$AB,26,0) -> 280000 | J37: =I37*H37 -> 280000 | K37: =J37*1.08 -> 302400 | N37: 45658 | O37: =N37-L37 -> 45658 | P37: =MONTH(N37) -> 1 | Q37: =YEAR(N37) -> 2025 | R37: Nhập kho | T37: 45709 | U37: =VLOOKUP($E37,'0. Mã Supplier'!$B:$F,5,0) -> 0 | V37: =T37+U37 -> 45709 | W37: =WEEKNUM(V37) -> 8 | X37: =IF(V37<>0,MONTH(V37),"") -> 2 | Y37: =YEAR(V37) -> 2025 | Z37: Yes | AA37: =IF(Z37="yes",0,TODAY()-V37) -> 0 | AB37: =IF(Z37="Yes",K37) -> 302400 | AD37: =IFERROR(K37-AB37,0) -> 0
A38: HHN-001 | B38: BLA001004 | C38: =VLOOKUP(B38,'1. Master Data'!$C:$K,9,0) -> Chăn Lạnh 4.8 Xanh lá pastel 200 x 230 cm, Vải cooling mát lạnh | D38: =VLOOKUP(E38,'0. Mã Supplier'!$B:$C,2,0) -> SUVN0001 | E38: HUY HOÀNG NAM | F38: Cái | G38: 4 | H38: 4 | I38: =VLOOKUP($B38,'1. Master Data'!$C:$AB,26,0) -> 280000 | J38: =I38*H38 -> 1120000 | K38: =J38*1.08 -> 1209600 | N38: 45658 | O38: =N38-L38 -> 45658 | P38: =MONTH(N38) -> 1 | Q38: =YEAR(N38) -> 2025 | R38: Nhập kho | T38: 45709 | U38: =VLOOKUP($E38,'0. Mã Supplier'!$B:$F,5,0) -> 0 | V38: =T38+U38 -> 45709 | W38: =WEEKNUM(V38) -> 8 | X38: =IF(V38<>0,MONTH(V38),"") -> 2 | Y38: =YEAR(V38) -> 2025 | Z38: Yes | AA38: =IF(Z38="yes",0,TODAY()-V38) -> 0 | AB38: =IF(Z38="Yes",K38) -> 1209600 | AD38: =IFERROR(K38-AB38,0) -> 0
A39: HHN-001 | B39: SET001001 | C39: =VLOOKUP(B39,'1. Master Data'!$C:$K,9,0) -> Bộ Chăn ga Xơ đũi 4CT (ga phủ, chăn chần) Trái tim | D39: =VLOOKUP(E39,'0. Mã Supplier'!$B:$C,2,0) -> SUVN0001 | E39: HUY HOÀNG NAM | F39: Bộ | G39: 13 | H39: 13 | I39: =VLOOKUP($B39,'1. Master Data'!$C:$AB,26,0) -> 207900 | J39: =I39*H39 -> 2702700 | K39: =J39*1.08 -> 2918916 | N39: 45658 | O39: =N39-L39 -> 45658 | P39: =MONTH(N39) -> 1 | Q39: =YEAR(N39) -> 2025 | R39: Nhập kho | T39: 45709 | U39: =VLOOKUP($E39,'0. Mã Supplier'!$B:$F,5,0) -> 0 | V39: =T39+U39 -> 45709 | W39: =WEEKNUM(V39) -> 8 | X39: =IF(V39<>0,MONTH(V39),"") -> 2 | Y39: =YEAR(V39) -> 2025 | Z39: Yes | AA39: =IF(Z39="yes",0,TODAY()-V39) -> 0 | AB39: =IF(Z39="Yes",K39) -> 2918916 | AD39: =IFERROR(K39-AB39,0) -> 0
... A69: HHN-003 | B69: SET002002 | C69: =VLOOKUP(B69,'1. Master Data'!$C:$K,9,0) -> Bộ Chăn ga phủ vỏ chăn 4CT Mẫu 2 | D69: =VLOOKUP(E69,'0. Mã Supplier'!$B:$C,2,0) -> SUVN0001 | E69: HUY HOÀNG NAM | F69: Bộ | G69: 3 | H69: 3 | I69: =VLOOKUP($B69,'1. Master Data'!$C:$AB,26,0) -> 199100 | J69: =I69*H69 -> 597300 | K69: =J69*1.08 -> 645084 | N69: 45717 | O69: =N69-L69 -> 45717 | P69: =MONTH(N69) -> 3 | Q69: =YEAR(N69) -> 2025 | R69: Nhập kho | T69: 45734 | U69: =VLOOKUP($E69,'0. Mã Supplier'!$B:$F,5,0) -> 0 | V69: =T69+U69 -> 45734 | W69: =WEEKNUM(V69) -> 12 | X69: =IF(V69<>0,MONTH(V69),"") -> 3 | Y69: =YEAR(V69) -> 2025 | Z69: Yes | AA69: =IF(Z69="yes",0,TODAY()-V69) -> 0 | AB69: =IF(Z69="Yes",K69) -> 645084 | AD69: =IFERROR(K69-AB69,0) -> 0
A70: HHN-004 | B70: BLA001001 | C70: =VLOOKUP(B70,'1. Master Data'!$C:$K,9,0) -> Chăn Lạnh 4.8 Xanh dương pastel 200 x 230 cm, Vải cooling mát lạnh | D70: =VLOOKUP(E70,'0. Mã Supplier'!$B:$C,2,0) -> SUVN0001 | E70: HUY HOÀNG NAM | F70: Cái | G70: 10 | H70: 10 | I70: =VLOOKUP($B70,'1. Master Data'!$C:$AB,26,0) -> 280000 | J70: =I70*H70 -> 2800000 | N70: 45748 | O70: =N70-L70 -> 45748 | P70: =MONTH(N70) -> 4 | Q70: =YEAR(N70) -> 2025 | R70: Nhập kho | T70: 45889 | U70: =VLOOKUP($E70,'0. Mã Supplier'!$B:$F,5,0) -> 0 | V70: =T70+U70 -> 45889 | W70: =WEEKNUM(V70) -> 34 | X70: =IF(V70<>0,MONTH(V70),"") -> 8 | Y70: =YEAR(V70) -> 2025 | AA70: =IF(Z70="yes",0,TODAY()-V70) -> 375 | AB70: =IF(Z70="Yes",K70) -> FALSE | AD70: =IFERROR(K70-AB70,0) -> 0
A71: HHN-004 | B71: BLA001002 | C71: =VLOOKUP(B71,'1. Master Data'!$C:$K,9,0) -> Chăn Lạnh 4.8 Xám pastel 200 x 230 cm, Vải cooling mát lạnh | D71: =VLOOKUP(E71,'0. Mã Supplier'!$B:$C,2,0) -> SUVN0001 | E71: HUY HOÀNG NAM | F71: Cái | G71: 10 | H71: 10 | I71: =VLOOKUP($B71,'1. Master Data'!$C:$AB,26,0) -> 280000 | J71: =I71*H71 -> 2800000 | N71: 45748 | O71: =N71-L71 -> 45748 | P71: =MONTH(N71) -> 4 | Q71: =YEAR(N71) -> 2025 | R71: Nhập kho | T71: 45889 | U71: =VLOOKUP($E71,'0. Mã Supplier'!$B:$F,5,0) -> 0 | V71: =T71+U71 -> 45889 | W71: =WEEKNUM(V71) -> 34 | X71: =IF(V71<>0,MONTH(V71),"") -> 8 | Y71: =YEAR(V71) -> 2025 | AA71: =IF(Z71="yes",0,TODAY()-V71) -> 375 | AB71: =IF(Z71="Yes",K71) -> FALSE | AD71: =IFERROR(K71-AB71,0) -> 0
A72: HHN-004 | B72: BLA001002 | C72: =VLOOKUP(B72,'1. Master Data'!$C:$K,9,0) -> Chăn Lạnh 4.8 Xám pastel 200 x 230 cm, Vải cooling mát lạnh | D72: =VLOOKUP(E72,'0. Mã Supplier'!$B:$C,2,0) -> SUVN0001 | E72: HUY HOÀNG NAM | F72: Cái | G72: 20 | H72: 20 | I72: =VLOOKUP($B72,'1. Master Data'!$C:$AB,26,0) -> 280000 | J72: =I72*H72 -> 5600000 | N72: 45748 | O72: =N72-L72 -> 45748 | P72: =MONTH(N72) -> 4 | Q72: =YEAR(N72) -> 2025 | R72: Nhập kho | T72: 45889 | U72: =VLOOKUP($E72,'0. Mã Supplier'!$B:$F,5,0) -> 0 | V72: =T72+U72 -> 45889 | W72: =WEEKNUM(V72) -> 34 | X72: =IF(V72<>0,MONTH(V72),"") -> 8 | Y72: =YEAR(V72) -> 2025 | AA72: =IF(Z72="yes",0,TODAY()-V72) -> 375 | AB72: =IF(Z72="Yes",K72) -> FALSE | AD72: =IFERROR(K72-AB72,0) -> 0
A73: HHN-004 | B73: BLA001003 | C73: =VLOOKUP(B73,'1. Master Data'!$C:$K,9,0) -> Chăn Lạnh 4.8 Tím hoa cà 200 x 230 cm, Vải cooling mát lạnh | D73: =VLOOKUP(E73,'0. Mã Supplier'!$B:$C,2,0) -> SUVN0001 | E73: HUY HOÀNG NAM | F73: Cái | G73: 5 | H73: 5 | I73: =VLOOKUP($B73,'1. Master Data'!$C:$AB,26,0) -> 280000 | J73: =I73*H73 -> 1400000 | N73: 45748 | O73: =N73-L73 -> 45748 | P73: =MONTH(N73) -> 4 | Q73: =YEAR(N73) -> 2025 | R73: Nhập kho | T73: 45889 | U73: =VLOOKUP($E73,'0. Mã Supplier'!$B:$F,5,0) -> 0 | V73: =T73+U73 -> 45889 | W73: =WEEKNUM(V73) -> 34 | X73: =IF(V73<>0,MONTH(V73),"") -> 8 | Y73: =YEAR(V73) -> 2025 | AA73: =IF(Z73="yes",0,TODAY()-V73) -> 375 | AB73: =IF(Z73="Yes",K73) -> FALSE | AD73: =IFERROR(K73-AB73,0) -> 0
A74: HHN-004 | B74: BLA001004 | C74: =VLOOKUP(B74,'1. Master Data'!$C:$K,9,0) -> Chăn Lạnh 4.8 Xanh lá pastel 200 x 230 cm, Vải cooling mát lạnh | D74: =VLOOKUP(E74,'0. Mã Supplier'!$B:$C,2,0) -> SUVN0001 | E74: HUY HOÀNG NAM | F74: Cái | G74: 5 | H74: 5 | I74: =VLOOKUP($B74,'1. Master Data'!$C:$AB,26,0) -> 280000 | J74: =I74*H74 -> 1400000 | N74: 45748 | O74: =N74-L74 -> 45748 | P74: =MONTH(N74) -> 4 | Q74: =YEAR(N74) -> 2025 | R74: Nhập kho | T74: 45889 | U74: =VLOOKUP($E74,'0. Mã Supplier'!$B:$F,5,0) -> 0 | V74: =T74+U74 -> 45889 | W74: =WEEKNUM(V74) -> 34 | X74: =IF(V74<>0,MONTH(V74),"") -> 8 | Y74: =YEAR(V74) -> 2025 | AA74: =IF(Z74="yes",0,TODAY()-V74) -> 375 | AB74: =IF(Z74="Yes",K74) -> FALSE | AD74: =IFERROR(K74-AB74,0) -> 0
A75: HHN-004 | B75: SET001001 | C75: =VLOOKUP(B75,'1. Master Data'!$C:$K,9,0) -> Bộ Chăn ga Xơ đũi 4CT (ga phủ, chăn chần) Trái tim | D75: =VLOOKUP(E75,'0. Mã Supplier'!$B:$C,2,0) -> SUVN0001 | E75: HUY HOÀNG NAM | F75: Bộ | G75: 10 | H75: 10 | I75: =VLOOKUP($B75,'1. Master Data'!$C:$AB,26,0) -> 207900 | J75: =I75*H75 -> 2079000 | N75: 45748 | O75: =N75-L75 -> 45748 | P75: =MONTH(N75) -> 4 | Q75: =YEAR(N75) -> 2025 | R75: Nhập kho | T75: 45889 | U75: =VLOOKUP($E75,'0. Mã Supplier'!$B:$F,5,0) -> 0 | V75: =T75+U75 -> 45889 | W75: =WEEKNUM(V75) -> 34 | X75: =IF(V75<>0,MONTH(V75),"") -> 8 | Y75: =YEAR(V75) -> 2025 | AA75: =IF(Z75="yes",0,TODAY()-V75) -> 375 | AB75: =IF(Z75="Yes",K75) -> FALSE | AD75: =IFERROR(K75-AB75,0) -> 0
A76: HHN-004 | B76: SET002001 | C76: =VLOOKUP(B76,'1. Master Data'!$C:$K,9,0) -> Bộ Chăn ga phủ vỏ chăn 4CT Mẫu 1 | D76: =VLOOKUP(E76,'0. Mã Supplier'!$B:$C,2,0) -> SUVN0001 | E76: HUY HOÀNG NAM | F76: Bộ | G76: 2 | H76: 2 | I76: =VLOOKUP($B76,'1. Master Data'!$C:$AB,26,0) -> 199100 | J76: =I76*H76 -> 398200 | N76: 45748 | O76: =N76-L76 -> 45748 | P76: =MONTH(N76) -> 4 | Q76: =YEAR(N76) -> 2025 | R76: Nhập kho | T76: 45889 | U76: =VLOOKUP($E76,'0. Mã Supplier'!$B:$F,5,0) -> 0 | V76: =T76+U76 -> 45889 | W76: =WEEKNUM(V76) -> 34 | X76: =IF(V76<>0,MONTH(V76),"") -> 8 | Y76: =YEAR(V76) -> 2025 | AA76: =IF(Z76="yes",0,TODAY()-V76) -> 375 | AB76: =IF(Z76="Yes",K76) -> FALSE | AD76: =IFERROR(K76-AB76,0) -> 0
A77: HHN-004 | B77: SET002002 | C77: =VLOOKUP(B77,'1. Master Data'!$C:$K,9,0) -> Bộ Chăn ga phủ vỏ chăn 4CT Mẫu 2 | D77: =VLOOKUP(E77,'0. Mã Supplier'!$B:$C,2,0) -> SUVN0001 | E77: HUY HOÀNG NAM | F77: Bộ | G77: 3 | H77: 3 | I77: =VLOOKUP($B77,'1. Master Data'!$C:$AB,26,0) -> 199100 | J77: =I77*H77 -> 597300 | N77: 45748 | O77: =N77-L77 -> 45748 | P77: =MONTH(N77) -> 4 | Q77: =YEAR(N77) -> 2025 | R77: Nhập kho | T77: 45889 | U77: =VLOOKUP($E77,'0. Mã Supplier'!$B:$F,5,0) -> 0 | V77: =T77+U77 -> 45889 | W77: =WEEKNUM(V77) -> 34 | X77: =IF(V77<>0,MONTH(V77),"") -> 8 | Y77: =YEAR(V77) -> 2025 | AA77: =IF(Z77="yes",0,TODAY()-V77) -> 375 | AB77: =IF(Z77="Yes",K77) -> FALSE | AD77: =IFERROR(K77-AB77,0) -> 0
A78: HHN-004 | B78: SET002003 | C78: =VLOOKUP(B78,'1. Master Data'!$C:$K,9,0) -> Bộ Chăn ga phủ vỏ chăn 4CT Mẫu 3 | D78: =VLOOKUP(E78,'0. Mã Supplier'!$B:$C,2,0) -> SUVN0001 | E78: HUY HOÀNG NAM | F78: Bộ | G78: 3 | H78: 3 | I78: =VLOOKUP($B78,'1. Master Data'!$C:$AB,26,0) -> 199100 | J78: =I78*H78 -> 597300 | N78: 45748 | O78: =N78-L78 -> 45748 | P78: =MONTH(N78) -> 4 | Q78: =YEAR(N78) -> 2025 | R78: Nhập kho | T78: 45889 | U78: =VLOOKUP($E78,'0. Mã Supplier'!$B:$F,5,0) -> 0 | V78: =T78+U78 -> 45889 | W78: =WEEKNUM(V78) -> 34 | X78: =IF(V78<>0,MONTH(V78),"") -> 8 | Y78: =YEAR(V78) -> 2025 | AA78: =IF(Z78="yes",0,TODAY()-V78) -> 375 | AB78: =IF(Z78="Yes",K78) -> FALSE | AD78: =IFERROR(K78-AB78,0) -> 0
A79: HHN-004 | B79: SET002004 | C79: =VLOOKUP(B79,'1. Master Data'!$C:$K,9,0) -> Bộ Chăn ga phủ vỏ chăn 4CT Mẫu 4 | D79: =VLOOKUP(E79,'0. Mã Supplier'!$B:$C,2,0) -> SUVN0001 | E79: HUY HOÀNG NAM | F79: Bộ | G79: 2 | H79: 2 | I79: =VLOOKUP($B79,'1. Master Data'!$C:$AB,26,0) -> 199100 | J79: =I79*H79 -> 398200 | N79: 45748 | O79: =N79-L79 -> 45748 | P79: =MONTH(N79) -> 4 | Q79: =YEAR(N79) -> 2025 | R79: Nhập kho | T79: 45889 | U79: =VLOOKUP($E79,'0. Mã Supplier'!$B:$F,5,0) -> 0 | V79: =T79+U79 -> 45889 | W79: =WEEKNUM(V79) -> 34 | X79: =IF(V79<>0,MONTH(V79),"") -> 8 | Y79: =YEAR(V79) -> 2025 | AA79: =IF(Z79="yes",0,TODAY()-V79) -> 375 | AB79: =IF(Z79="Yes",K79) -> FALSE | AD79: =IFERROR(K79-AB79,0) -> 0
A80: HHN-004 | B80: SET002006 | C80: =VLOOKUP(B80,'1. Master Data'!$C:$K,9,0) -> Bộ Chăn ga phủ vỏ chăn 4CT Mẫu 6 | D80: =VLOOKUP(E80,'0. Mã Supplier'!$B:$C,2,0) -> SUVN0001 | E80: HUY HOÀNG NAM | F80: Bộ | G80: 5 | H80: 5 | I80: =VLOOKUP($B80,'1. Master Data'!$C:$AB,26,0) -> 199100 | J80: =I80*H80 -> 995500 | N80: 45748 | O80: =N80-L80 -> 45748 | P80: =MONTH(N80) -> 4 | Q80: =YEAR(N80) -> 2025 | R80: Nhập kho | T80: 45889 | U80: =VLOOKUP($E80,'0. Mã Supplier'!$B:$F,5,0) -> 0 | V80: =T80+U80 -> 45889 | W80: =WEEKNUM(V80) -> 34 | X80: =IF(V80<>0,MONTH(V80),"") -> 8 | Y80: =YEAR(V80) -> 2025 | AA80: =IF(Z80="yes",0,TODAY()-V80) -> 375 | AB80: =IF(Z80="Yes",K80) -> FALSE | AD80: =IFERROR(K80-AB80,0) -> 0
A81: HHN-005 | B81: BLA001001 | C81: =VLOOKUP(B81,'1. Master Data'!$C:$K,9,0) -> Chăn Lạnh 4.8 Xanh dương pastel 200 x 230 cm, Vải cooling mát lạnh | D81: =VLOOKUP(E81,'0. Mã Supplier'!$B:$C,2,0) -> SUVN0001 | E81: HUY HOÀNG NAM | F81: Cái | G81: 50 | H81: 50 | I81: =VLOOKUP($B81,'1. Master Data'!$C:$AB,26,0) -> 280000 | J81: =I81*H81 -> 14000000 | N81: 45778 | O81: =N81-L81 -> 45778 | P81: =MONTH(N81) -> 5 | Q81: =YEAR(N81) -> 2025 | R81: Nhập kho | T81: 45889 | U81: =VLOOKUP($E81,'0. Mã Supplier'!$B:$F,5,0) -> 0 | V81: =T81+U81 -> 45889 | W81: =WEEKNUM(V81) -> 34 | X81: =IF(V81<>0,MONTH(V81),"") -> 8 | Y81: =YEAR(V81) -> 2025 | AA81: =IF(Z81="yes",0,TODAY()-V81) -> 375 | AB81: =IF(Z81="Yes",K81) -> FALSE | AD81: =IFERROR(K81-AB81,0) -> 0
... A90: HHN-006 | B90: BLA002001 | C90: =VLOOKUP(B90,'1. Master Data'!$C:$K,9,0) -> Chăn Tencel 60s Xanh dương pastel 200 x 230 cm | D90: =VLOOKUP(E90,'0. Mã Supplier'!$B:$C,2,0) -> SUVN0001 | E90: HUY HOÀNG NAM | F90: Cái | G90: 7 | H90: 7 | I90: =VLOOKUP($B90,'1. Master Data'!$C:$AB,26,0) -> 429000 | J90: =I90*H90 -> 3003000 | N90: 45809 | O90: =N90-L90 -> 45809 | P90: =MONTH(N90) -> 6 | Q90: =YEAR(N90) -> 2025 | R90: Nhập kho | T90: 45889 | U90: =VLOOKUP($E90,'0. Mã Supplier'!$B:$F,5,0) -> 0 | V90: =T90+U90 -> 45889 | W90: =WEEKNUM(V90) -> 34 | X90: =IF(V90<>0,MONTH(V90),"") -> 8 | Y90: =YEAR(V90) -> 2025 | AA90: =IF(Z90="yes",0,TODAY()-V90) -> 375 | AB90: =IF(Z90="Yes",K90) -> FALSE | AD90: =IFERROR(K90-AB90,0) -> 0
...

Sheet Mã Kho
A1: Mã kho | B1: Tên kho | C1: Loại kho | D1: Địa chỉ
A2: WH01 | B2: Kho thuê-ACE HOME | C2: Kho bán hàng | D2: Thành phố Hồ Chí Minh Phường Bình Đông Kho 14 kim hằng, số 1 Ba Tơ ( Trịnh Quang Nghị),(VN)
A3: WH02 | B3: Kho Cửa Hàng D9 | C3: Kho bán hàng | D3: Tỉnh Đồng Nai Phường Trấn Biên E97, Đường D 9 Võ Thị Sáu, Phường Trấn Biên, Tỉnh Đồng Nai, Việt Nam,(VN)
A4: WH03 | B4: Kho Everhome | C4: Kho bán hàng | D4: Thành phố Hà Nội Xã Hòa Lạc Công Ty Cổ Phàn Quốc Tế Everhome, Thôn 1, Xã Hòa Lạc, Thành phố Hà Nội, Việt Nam,(VN)
A5: WH04 | B5: Kho hàng lỗi | C5: Kho lưu trữ | D5: Tỉnh Đồng Nai Phường Trấn Biên E97, Đường D 9 Võ Thị Sáu, Phường Trấn Biên, Tỉnh Đồng Nai, Việt Nam,(VN)
